# `Error`实例对象

```javascript
var err = new Error('出错了');
err.message // "出错了"
```

`Error`构造函数接受一个参数表示错误提示。

抛出`Error`实例对象后，整个程序就在发生错误的地方中断，不再执行

语言标准要求`Error`必须有`message`属性，但大多数JavaScript引擎还提供了另外两种属性：

+ **message**：错误提示信息
+ **name**：错误名称（非标准属性）
+ **stack**：错误的堆栈（非标准属性）

```javascript
//name属性
if (error.name) {
  console.log(error.name + ': ' + error.message);
}

//stack属性
function throwit() {
  throw new Error('');
}

function catchit() {
  try {
    throwit();
  } catch(e) {
    console.log(e.stack); // print stack trace
  }
}

catchit()
// Error
//    at throwit (~/examples/throwcatch.js:9:11)
//    at catchit (~/examples/throwcatch.js:3:9)
//    at repl:1:5

//先找出最内层函数，然后是外层函数，然后是函数的运行环境
```

# 原生错误类型

## `SyntaxError`对象

解析代码时发生的语法错误

```javascript
// 变量名错误
var 1a;
// Uncaught SyntaxError: Invalid or unexpected token

// 缺少括号
console.log 'hello');
// Uncaught SyntaxError: Unexpected string
```

## `ReferenceError`对象

引用一个不存在的变量时发生的错误

```javascript
// 使用一个不存在的变量
unknownVariable
// Uncaught ReferenceError: unknownVariable is not defined
```

或是将一个值分配给了一个无法分配的对象，如函数的运行结果或者`this`赋值

```javascript
// 等号左侧不是变量
console.log() = 1
// Uncaught ReferenceError: Invalid left-hand side in assignment

// this 对象不能手动赋值
this = 1
// ReferenceError: Invalid left-hand side in assignment
```

## `RangeError`对象

一个值超出有效范围时发生的错误。如：

1. 数组长度为负数
2. `Number`对象的方法参数超出范围
3. 函数堆栈超过最大值

```javascript
// 数组长度不得为负数
new Array(-1)
// Uncaught RangeError: Invalid array length
```

## `TypeError`对象

变量或参数不是预期类型时发生的错误，或调用对象不存在的方法

```javascript
new 123
// Uncaught TypeError: number is not a func

var obj = {};
obj.unknownMethod()
// Uncaught TypeError: obj.unknownMethod is not a function
```

## `URIError`对象

URI相关函数的参数不正确时抛出的错误。

主要涉及：

+ `encodeURI()`
+ `decodeURI()`
+ `encodeURIComponent()`
+ `decodeURIComponent()`
+ `esacpe()`
+ `unescape()`

```javascript
decodeURI('%2')
// URIError: URI malformed
```

## `EvalError`对象 ==弃用==

`eval`函数没有被正确执行时抛出。

但该类型已经不再使用，为了与以前代码兼容才保留。

# 自定义错误

```javascript
function UserError(message) {
  this.message = message || '默认信息';
  this.name = 'UserError';
}

UserError.prototype = new Error();
UserError.prototype.constructor = UserError;
```



# 错误处理

两种错误：

1. 程序逻辑错误，代码执行异常
2. 程序遭遇无法预测的异常情况，如网络连接中断、读取不存在的文件，没有操作权限等

## `try...catch...finally`

```javascript
var r1, r2, s = null;
try {
    r1 = s.length; // 此处应产生错误
    r2 = 100; // 该语句不会执行
} catch (e) {
    console.log('出错了：' + e);
} finally {
    console.log('finally');
}
console.log('r1 = ' + r1); // r1应为undefined
console.log('r2 = ' + r2); // r2应为undefined

```

`try{...}`包含的代码表示执行过程中可能会发生错误，若发生了错误就不再继续执行，跳转到`catch(e){...}`块，若没有发生错误，则不会执行`catch(e){...}`的代码；

`catch(e){...}`包裹的代码是错误处理代码，变量`e`表示捕获到的错误；

`finally`包裹的代码无论是否发生错误都会执行。

> `catch`与`finally`可以忽略，不必都出现，视情况需要

`try`语句在`finally`代码执行前就执行，但会等到`finally`代码执行完毕再返回：

```javascript
var count = 0;
function countUp() {
  try {
    return count;
  } finally {
    count++;
  }
}

countUp()
// 0
count
// 1
```

### `try`、`catch`、`finally`执行顺序

1. 若存在`finally`语句，在`try`与`catch`中的`return`语句在执行之前都会先执行`finally`语句
2. 若`finally`中有`return`语句，那么直接return
3. 若`finally`中无`return`语句，则执行完毕后返回`try`或`catch`（取决与`catch`是否存在）中执行`return`语句

## `throw`语句 抛出错误

使用`throw`语句使执行流程直接跳转到`catch`块

```javascript
var r, n, s;
try {
    s = prompt('请输入一个数字');
    n = parseInt(s);
    if (isNaN(n)) {
        throw new Error('输入错误');
    }
    // 计算平方:
    r = n * n;
    console.log(n + ' * ' + n + ' = ' + r);
} catch (e) {
    console.log('出错了：' + e);  // 出错了：Error:输入错误
}
```

JavaScript允许抛出任意对象，包括数字、字符串。但是，最好还是抛出一个Error对象。

```javascript
throw ('输入错误')
```

==使用`catch`捕获错误时一定要编写错误处理语句==

# 错误传播

如果在一个函数内部发生了错误，它自身没有捕获，错误就会被抛到外层调用函数，如果外层函数也没有捕获，该错误会一直沿着函数调用链向上抛出，直到被JavaScript引擎捕获，代码终止执行。

```javascript
function main(s) {
    console.log('BEGIN main()');
    try {
        foo(s);
    } catch (e) {
        console.log('出错了：' + e);
    }
    console.log('END main()');
}

function foo(s) {
    console.log('BEGIN foo()');
    bar(s);
    console.log('END foo()');
}

function bar(s) {
    console.log('BEGIN bar()');
    console.log('length = ' + s.length);
    console.log('END bar()');
}

main(null);

```

```javascript
//调试结果：
BEGIN main()
BEGIN foo()
BEGIN bar()
出错了：TypeError: Cannot read property 'length' of null
END main()
```

# 异步错误处理

```javascript
function printTime() {
    throw new Error();
}

try {
    setTimeout(printTime, 1000);
    console.log('done');
} catch (e) {
    console.log('error');
}
// done
```

在调用`setTimeout()`函数时，传入的`printTime`函数并没有立刻执行，1秒后才开始执行并发生错误，但该错误只在`printTime`函数内部捕获到错误。

解决方法：

```javascript
setTimeout(function(){
    try{
        printTime();
    }catch(e){
        console.log(e);
    }
}, 1000)
```

哪里出现错误就在哪里使用`try`、`catch`捕获